Error executing job with overrides: ['datasets=train_test', 'index=97']
Traceback (most recent call last):
  File "/home1/mpgee/.conda/envs/gift/lib/python3.11/site-packages/hydra/_internal/instantiate/_instantiate2.py", line 92, in _call_target
    return _target_(*args, **kwargs)
           ^^^^^^^^^^^^^^^^^^^^^^^^^
  File "/home1/mpgee/gift-eval/src/gift_eval/analysis/analyzer.py", line 167, in __init__
    self.datasets = [datasets[index]]
                     ~~~~~~~~^^^^^^^
IndexError: list index out of range

The above exception was the direct cause of the following exception:

Traceback (most recent call last):
  File "<frozen runpy>", line 198, in _run_module_as_main
  File "<frozen runpy>", line 88, in _run_code
  File "/home1/mpgee/gift-eval/cli/analysis.py", line 16, in <module>
    main()
  File "/home1/mpgee/.conda/envs/gift/lib/python3.11/site-packages/hydra/main.py", line 90, in decorated_main
    _run_hydra(
  File "/home1/mpgee/.conda/envs/gift/lib/python3.11/site-packages/hydra/_internal/utils.py", line 394, in _run_hydra
    _run_app(
  File "/home1/mpgee/.conda/envs/gift/lib/python3.11/site-packages/hydra/_internal/utils.py", line 457, in _run_app
    run_and_report(
  File "/home1/mpgee/.conda/envs/gift/lib/python3.11/site-packages/hydra/_internal/utils.py", line 222, in run_and_report
    raise ex
  File "/home1/mpgee/.conda/envs/gift/lib/python3.11/site-packages/hydra/_internal/utils.py", line 219, in run_and_report
    return func()
           ^^^^^^
  File "/home1/mpgee/.conda/envs/gift/lib/python3.11/site-packages/hydra/_internal/utils.py", line 458, in <lambda>
    lambda: hydra.run(
            ^^^^^^^^^^
  File "/home1/mpgee/.conda/envs/gift/lib/python3.11/site-packages/hydra/_internal/hydra.py", line 132, in run
    _ = ret.return_value
        ^^^^^^^^^^^^^^^^
  File "/home1/mpgee/.conda/envs/gift/lib/python3.11/site-packages/hydra/core/utils.py", line 260, in return_value
    raise self._return_value
  File "/home1/mpgee/.conda/envs/gift/lib/python3.11/site-packages/hydra/core/utils.py", line 186, in run_job
    ret.return_value = task_function(task_cfg)
                       ^^^^^^^^^^^^^^^^^^^^^^^
  File "/home1/mpgee/gift-eval/cli/analysis.py", line 10, in main
    analyzer = instantiate(cfg.analyzer, _convert_="all")
               ^^^^^^^^^^^^^^^^^^^^^^^^^^^^^^^^^^^^^^^^^^
  File "/home1/mpgee/.conda/envs/gift/lib/python3.11/site-packages/hydra/_internal/instantiate/_instantiate2.py", line 226, in instantiate
    return instantiate_node(
           ^^^^^^^^^^^^^^^^^
  File "/home1/mpgee/.conda/envs/gift/lib/python3.11/site-packages/hydra/_internal/instantiate/_instantiate2.py", line 347, in instantiate_node
    return _call_target(_target_, partial, args, kwargs, full_key)
           ^^^^^^^^^^^^^^^^^^^^^^^^^^^^^^^^^^^^^^^^^^^^^^^^^^^^^^^
  File "/home1/mpgee/.conda/envs/gift/lib/python3.11/site-packages/hydra/_internal/instantiate/_instantiate2.py", line 97, in _call_target
    raise InstantiationException(msg) from e
hydra.errors.InstantiationException: Error in call to target 'gift_eval.analysis.analyzer.Analyzer':
IndexError('list index out of range')
full_key: analyzer
[Jun 16, 2025 08:21:54PM] ERROR: Dataset analysis failed!
